<?xml version='1.0'?>
<sdf version='1.7'>
  <model name='iris'> <!-- fichier .sdf qui défini la géométrie -->
    <pose>0 0 0.194923 0 0 0</pose>
    <link name='base_link'>  
      <velocity_decay>
        <linear>0.0</linear>
        <angular>0.0</angular>
      </velocity_decay>
      <inertial>  <!-- inertie du corps du drone -->
        <pose>0 0 0 0 0 0</pose>
        <mass>2.3</mass>
        <inertia>
           <ixx>0.0364167</ixx>
          <ixy>0</ixy>
          <ixz>0</ixz>
          <iyy>0.0364167</iyy>
          <iyz>0</iyz>
          <izz>0.071875</izz>
        </inertia>
      </inertial>
      <collision name='base_link_collision'> <!-- zone de collision du corps du drone -->
        <pose>0 0 -0.031 0 0 0</pose>
        <geometry>
          <cylinder>
            <length>0.04</length>
            <radius>0.11</radius>
          </cylinder>
        </geometry>
        <surface>
          <contact>
            <ode>
              <max_vel>100.0</max_vel>
              <min_depth>0.001</min_depth>
            </ode>
          </contact>
          <friction>
            <ode>
              <mu>100000.0</mu>
              <mu2>100000.0</mu2>
            </ode>
          </friction>
        </surface>
      </collision>    

      <!-- <visual name='collision visual for debbuging'> 
        <pose>0.231922 -0.1339 -0.04 0 -0 2.61799</pose>
        <geometry>
          <cylinder>
            <length>0.05</length>
            <radius>0.0072</radius>
          </cylinder>
        </geometry>
        <material>
          <script>
            <name>Gazebo/Red</name>
            <uri>file://media/materials/scripts/gazebo.material</uri>
          </script>
        </material>
      </visual> -->

      <!-- zones de collision des pattes du drone -->
      <collision name='base_link_fixed_joint_lump__front_right_leg_clip_link_collision_1'>
        <pose>0.231922 -0.1339 -0.04 0 -0 2.61799</pose>
        <geometry>
          <cylinder>
            <length>0.05</length>
            <radius>0.0072</radius>
          </cylinder>
        </geometry>
        <surface>
          <contact>
            <ode>
              <min_depth>0.001</min_depth>
              <max_vel>0</max_vel>
            </ode>
          </contact>
          <friction>
            <ode/>
          </friction>
        </surface>
      </collision>
      <collision name='base_link_fixed_joint_lump__middle_left_leg_clip_link_collision_2'>
        <pose>0 0.2678 -0.04 0 0 -1.5708</pose>
        <geometry>
          <cylinder>
            <length>0.05</length>
            <radius>0.0072</radius>
          </cylinder>
        </geometry>
        <surface>
          <contact>
            <ode>
              <min_depth>0.001</min_depth>
              <max_vel>0</max_vel>
            </ode>
          </contact>
          <friction>
            <ode/>
          </friction>
        </surface>
      </collision>
      <collision name='base_link_fixed_joint_lump__rear_right_leg_clip_link_collision_3'>
        <pose>-0.231922 -0.1339 -0.04 0 -0 0.523599</pose>
        <geometry>
          <cylinder>
            <length>0.05</length>
            <radius>0.0072</radius>
          </cylinder>
        </geometry>
        <surface>
          <contact>
            <ode>
              <min_depth>0.001</min_depth>
              <max_vel>0</max_vel>
            </ode>
          </contact>
          <friction>
            <ode/>
          </friction>
        </surface>
      </collision>
      <collision name='base_link_fixed_joint_lump__front_right_leg_clip_link_collision_4'>
        <pose>0.231922 0.1339 -0.04 0 -0 2.61799</pose>
        <geometry>
          <cylinder>
            <length>0.05</length>
            <radius>0.0072</radius>
          </cylinder>
        </geometry>
        <surface>
          <contact>
            <ode>
              <min_depth>0.001</min_depth>
              <max_vel>0</max_vel>
            </ode>
          </contact>
          <friction>
            <ode/>
          </friction>
        </surface>
      </collision>
      <collision name='base_link_fixed_joint_lump__middle_left_leg_clip_link_collision_5'>
        <pose>0 -0.2678 -0.04 0 0 -1.5708</pose>
        <geometry>
          <cylinder>
            <length>0.05</length>
            <radius>0.0072</radius>
          </cylinder>
        </geometry>
        <surface>
          <contact>
            <ode>
              <min_depth>0.001</min_depth>
              <max_vel>0</max_vel>
            </ode>
          </contact>
          <friction>
            <ode/>
          </friction>
        </surface>
      </collision>
      <collision name='base_link_fixed_joint_lump__rear_right_leg_clip_link_collision_6'>
        <pose>-0.231922 0.1339 -0.04 0 -0 0.523599</pose>
        <geometry>
          <cylinder>
            <length>0.05</length>
            <radius>0.0072</radius>
          </cylinder>
        </geometry>
        <surface>
          <contact>
            <ode>
              <min_depth>0.001</min_depth>
              <max_vel>0</max_vel>
            </ode>
          </contact>
          <friction>
            <ode/>
          </friction>
        </surface>
      </collision>
      
      <!-- <visual name='base_link_fixed_joint_lump__NUC_link_visual'>
        <pose>0 0 0.023 0 -0 0</pose>
        <geometry>
          <mesh>
            <scale>0.001 0.001 0.001</scale>
            <uri>/home/simon/catkin_ws/src/drone_gaz/models/iris_with_standoffs/meshes/dji_f550_nuc.dae</uri>
          </mesh>
        </geometry>
        <material>
          <script>
            <name>Gazebo/DarkGrey</name>
            <uri>file://media/materials/scripts/gazebo.material</uri>
          </script>
        </material>
      </visual>
 -->

      <!-- visuels du corps du drone, définis par des fichiers .dae -->
      <visual name='base_link_fixed_joint_lump__back_left_arm_link_visual_1'>
        <pose>-0.095263 0.055 -0.012 0 -0 2.61799</pose>
        <geometry>
          <mesh>
            <scale>1 1 1</scale>
            <uri>/home/simon/catkin_ws/src/drone_gaz/models/iris_with_standoffs/meshes/dji_f550_arm.dae</uri>
          </mesh>
        </geometry>
        <material>
          <script>
            <name>Gazebo/Red</name>
            <uri>file://media/materials/scripts/gazebo.material</uri>
          </script>
        </material>
      </visual>
      <visual name='base_link_fixed_joint_lump__back_right_arm_link_visual_2'>
        <pose>-0.095263 -0.055 -0.012 0 0 -2.61799</pose>
        <geometry>
          <mesh>
            <scale>1 1 1</scale>
            <uri>/home/simon/catkin_ws/src/drone_gaz/models/iris_with_standoffs/meshes/dji_f550_arm.dae</uri>
          </mesh>
        </geometry>
        <material>
          <script>
            <name>Gazebo/Red</name>
            <uri>file://media/materials/scripts/gazebo.material</uri>
          </script>
        </material>
      </visual>
      <!-- <visual name='base_link_fixed_joint_lump__battery_link_visual_3'>
        <pose>0 0 -0.074 0 -0 3.14159</pose>
        <geometry>
          <box>
            <size>0.135 0.042 0.044</size>
          </box>
        </geometry>
        <material>
          <script>
            <name>Gazebo/Grey</name>
            <uri>file://media/materials/scripts/gazebo.material</uri>
          </script>
        </material>
      </visual>
      <visual name='base_link_fixed_joint_lump__battery_mount_link_visual_4'>
        <pose>0.03 0 -0.06 0 -0 3.14159</pose>
        <geometry>
          <mesh>
            <scale>0.001 0.001 0.001</scale>
            <uri>/home/simon/catkin_ws/src/drone_gaz/models/iris_with_standoffs/meshes/dji_f550_battery_and_garmin_mount.dae</uri>
          </mesh>
        </geometry>
        <material>
          <script>
            <name>Gazebo/DarkGrey</name>
            <uri>file://media/materials/scripts/gazebo.material</uri>
          </script>
        </material>
      </visual> -->
      <visual name='base_link_fixed_joint_lump__front_left_arm_link_visual_5'>
        <pose>0.095263 0.055 -0.012 0 -0 0.523599</pose>
        <geometry>
          <mesh>
            <scale>1 1 1</scale>
            <uri>/home/simon/catkin_ws/src/drone_gaz/models/iris_with_standoffs/meshes/dji_f550_arm.dae</uri>
          </mesh>
        </geometry>
        <material>
          <script>
            <name>Gazebo/White</name>
            <uri>file://media/materials/scripts/gazebo.material</uri>
          </script>
        </material>
      </visual>
      <visual name='base_link_fixed_joint_lump__front_left_rotor_link_visual_6'>
        <pose>0.238157 0.1375 -0.012 0 -0 0</pose>
        <geometry>
          <mesh>
            <scale>1 1 1</scale>
            <uri>/home/simon/catkin_ws/src/drone_gaz/models/iris_with_standoffs/meshes/dji_f550_rotor.dae</uri>
          </mesh>
        </geometry>
        <material>
          <script>
            <name>Gazebo/Black</name>
            <uri>file://media/materials/scripts/gazebo.material</uri>
          </script>
        </material>
      </visual>
      <visual name='base_link_fixed_joint_lump__front_right_arm_link_visual_7'>
        <pose>0.095263 -0.055 -0.012 0 0 -0.523599</pose>
        <geometry>
          <mesh>
            <scale>1 1 1</scale>
            <uri>/home/simon/catkin_ws/src/drone_gaz/models/iris_with_standoffs/meshes/dji_f550_arm.dae</uri>
          </mesh>
        </geometry>
        <material>
          <script>
            <name>Gazebo/White</name>
            <uri>file://media/materials/scripts/gazebo.material</uri>
          </script>
        </material>
      </visual>
      <!-- <visual name='base_link_fixed_joint_lump__front_right_leg_clip_link_visual_8'>
        <pose>0.231922 -0.1339 -0.11 0 -0 2.61799</pose>
        <geometry>
          <mesh>
            <scale>0.001 0.001 0.001</scale>
            <uri>/home/simon/catkin_ws/src/drone_gaz/models/iris_with_standoffs/meshes/dji_f550_leg_170mm.dae</uri>
          </mesh>
        </geometry>
        <material>
          <script>
            <name>Gazebo/White</name>
            <uri>file://media/materials/scripts/gazebo.material</uri>
          </script>
        </material>
      </visual> -->
      <visual name='base_link_fixed_joint_lump__front_right_rotor_link_visual_9'>
        <pose>0.238157 -0.1375 -0.012 0 -0 0</pose>
        <geometry>
          <mesh>
            <scale>1 1 1</scale>
            <uri>/home/simon/catkin_ws/src/drone_gaz/models/iris_with_standoffs/meshes/dji_f550_rotor.dae</uri>
          </mesh>
        </geometry>
        <material>
          <script>
            <name>Gazebo/Black</name>
            <uri>file://media/materials/scripts/gazebo.material</uri>
          </script>
        </material>
      </visual>
      <visual name='base_link_fixed_joint_lump__lower_central_board_link_visual_10'>
        <pose>0 0 -0.05 0 -0 0.523599</pose>
        <geometry>
          <mesh>
            <scale>1 1 1</scale>
            <uri>/home/simon/catkin_ws/src/drone_gaz/models/iris_with_standoffs/meshes/dji_f550_central_board.dae</uri>
          </mesh>
        </geometry>
        <material>
          <script>
            <name>Gazebo/DarkGrey</name>
            <uri>file://media/materials/scripts/gazebo.material</uri>
          </script>
        </material>
      </visual>
      <visual name='base_link_fixed_joint_lump__middle_left_arm_link_visual_11'>
        <pose>0 0.11 -0.012 0 -0 1.5708</pose>
        <geometry>
          <mesh>
            <scale>1 1 1</scale>
            <uri>/home/simon/catkin_ws/src/drone_gaz/models/iris_with_standoffs/meshes/dji_f550_arm.dae</uri>
          </mesh>
        </geometry>
        <material>
          <script>
            <name>Gazebo/White</name>
            <uri>file://media/materials/scripts/gazebo.material</uri>
          </script>
        </material>
      </visual>
      <!-- <visual name='base_link_fixed_joint_lump__middle_left_leg_clip_link_visual_12'>
        <pose>0 0.2678 -0.11 0 0 -1.5708</pose>
        <geometry>
          <mesh>
            <scale>0.001 0.001 0.001</scale>
            <uri>/home/simon/catkin_ws/src/drone_gaz/models/iris_with_standoffs/meshes/dji_f550_leg_170mm.dae</uri>
          </mesh>
        </geometry>
        <material>
          <script>
            <name>Gazebo/White</name>
            <uri>file://media/materials/scripts/gazebo.material</uri>
          </script>
        </material>
      </visual> -->
      <visual name='base_link_fixed_joint_lump__middle_left_rotor_link_visual_13'>
        <pose>0 0.275 -0.012 0 -0 0</pose>
        <geometry>
          <mesh>
            <scale>1 1 1</scale>
            <uri>/home/simon/catkin_ws/src/drone_gaz/models/iris_with_standoffs/meshes/dji_f550_rotor.dae</uri>
          </mesh>
        </geometry>
        <material>
          <script>
            <name>Gazebo/Black</name>
            <uri>file://media/materials/scripts/gazebo.material</uri>
          </script>
        </material>
      </visual>
      <visual name='base_link_fixed_joint_lump__middle_right_arm_link_visual_14'>
        <pose>0 -0.11 -0.012 0 0 -1.5708</pose>
        <geometry>
          <mesh>
            <scale>1 1 1</scale>
            <uri>/home/simon/catkin_ws/src/drone_gaz/models/iris_with_standoffs/meshes/dji_f550_arm.dae</uri>
          </mesh>
        </geometry>
        <material>
          <script>
            <name>Gazebo/White</name>
            <uri>file://media/materials/scripts/gazebo.material</uri>
          </script>
        </material>
      </visual>
      <visual name='base_link_fixed_joint_lump__middle_right_rotor_link_visual_15'>
        <pose>0 -0.275 -0.012 0 -0 0</pose>
        <geometry>
          <mesh>
            <scale>1 1 1</scale>
            <uri>/home/simon/catkin_ws/src/drone_gaz/models/iris_with_standoffs/meshes/dji_f550_rotor.dae</uri>
          </mesh>
        </geometry>
        <material>
          <script>
            <name>Gazebo/Black</name>
            <uri>file://media/materials/scripts/gazebo.material</uri>
          </script>
        </material>
      </visual>
      <visual name='base_link_fixed_joint_lump__pixhawk_link_visual_16'>
        <pose>0 0 -0.0425 0 -0 0</pose>
        <geometry>
          <mesh>
            <scale>1 1 1</scale>
            <uri>/home/simon/catkin_ws/src/drone_gaz/models/mrs_robots_description/meshes/sensors/pixhawk.dae</uri>
          </mesh>
        </geometry>
        <material>
          <script>
            <name>Gazebo/DarkGrey</name>
            <uri>file://media/materials/scripts/gazebo.material</uri>
          </script>
        </material>
      </visual>
      <visual name='base_link_fixed_joint_lump__rear_left_rotor_link_visual_17'>
        <pose>-0.238157 0.1375 -0.012 0 -0 0</pose>
        <geometry>
          <mesh>
            <scale>1 1 1</scale>
            <uri>/home/simon/catkin_ws/src/drone_gaz/models/iris_with_standoffs/meshes/dji_f550_rotor.dae</uri>
          </mesh>
        </geometry>
        <material>
          <script>
            <name>Gazebo/Black</name>
            <uri>file://media/materials/scripts/gazebo.material</uri>
          </script>
        </material>
      </visual>
      <!-- <visual name='base_link_fixed_joint_lump__rear_right_leg_clip_link_visual_18'>
        <pose>-0.231922 -0.1339 -0.11 0 -0 0.523599</pose>
        <geometry>
          <mesh>
            <scale>0.001 0.001 0.001</scale>
            <uri>/home/simon/catkin_ws/src/drone_gaz/models/iris_with_standoffs/meshes/dji_f550_leg_170mm.dae</uri>
          </mesh>
        </geometry>
        <material>
          <script>
            <name>Gazebo/White</name>
            <uri>file://media/materials/scripts/gazebo.material</uri>
          </script>
        </material>
      </visual> -->
      <visual name='base_link_fixed_joint_lump__rear_right_rotor_link_visual_19'>
        <pose>-0.238157 -0.1375 -0.012 0 -0 0</pose>
        <geometry>
          <mesh>
            <scale>1 1 1</scale>
            <uri>/home/simon/catkin_ws/src/drone_gaz/models/iris_with_standoffs/meshes/dji_f550_rotor.dae</uri>
          </mesh>
        </geometry>
        <material>
          <script>
            <name>Gazebo/Black</name>
            <uri>file://media/materials/scripts/gazebo.material</uri>
          </script>
        </material>
      </visual>
      <visual name='base_link_fixed_joint_lump__upper_central_board_link_visual_20'>
        <pose>0 0 -0.012 0 -0 0.523599</pose>
        <geometry>
          <mesh>
            <scale>1 1 1</scale>
            <uri>/home/simon/catkin_ws/src/drone_gaz/models/iris_with_standoffs/meshes/dji_f550_central_board.dae</uri>
          </mesh>
        </geometry>
        <material>
          <script>
            <name>Gazebo/DarkGrey</name>
            <uri>file://media/materials/scripts/gazebo.material</uri>
          </script>
        </material>
      </visual>
     </link>

    <!-- capteurs -->
    <link name='iris/ground_truth/odometry_sensorgt_link'>
      <pose>0 0 0 0 -0 0</pose>
      <inertial>
        <pose>0 0 0 0 -0 0</pose>
        <mass>0.15</mass>
        <inertia>
          <ixx>0.0001</ixx>
          <ixy>0</ixy>
          <ixz>0</ixz>
          <iyy>0.0002</iyy>
          <iyz>0</iyz>
          <izz>0.0002</izz>
        </inertia>
      </inertial>
    </link>
    <joint name='iris/ground_truth/odometry_sensorgt_joint' type='revolute'>
      <child>iris/ground_truth/odometry_sensorgt_link</child>
      <parent>base_link</parent>
      <axis>
        <xyz>0 0 1</xyz>
        <limit>
          <lower>0</lower>
          <upper>0</upper>
          <effort>0</effort>
          <velocity>0</velocity>
        </limit>
        <dynamics>
          <damping>1.0</damping>
        </dynamics>
        <use_parent_model_frame>1</use_parent_model_frame>
      </axis>
      <physics>
        <ode>
          <implicit_spring_damper>1</implicit_spring_damper>
        </ode>
      </physics>
    </joint>
    <link name='iris/imu_link'>
      <inertial>
        <pose>0 0 0 0 0 0</pose>
        <mass>0.15</mass>
        <inertia>
          <ixx>0.00001</ixx>
          <ixy>0</ixy>
          <ixz>0</ixz>
          <iyy>0.00002</iyy>
          <iyz>0</iyz>
          <izz>0.00002</izz>
        </inertia>
      </inertial>
      <sensor name="imu_sensor" type="imu">
        <pose>0 0 0 3.141593 0 0</pose>
        <always_on>1</always_on>
        <update_rate>1000.0</update_rate>
      </sensor>
    </link>
    <joint name='iris/imu_joint' type='revolute'>
      <child>iris/imu_link</child>
      <parent>base_link</parent>
      <axis>
        <xyz>0 0 1</xyz>
        <limit>
          <lower>0</lower>
          <upper>0</upper>
          <effort>0</effort>
          <velocity>0</velocity>
        </limit>
        <dynamics>
          <damping>1.0</damping>
        </dynamics>
        <use_parent_model_frame>1</use_parent_model_frame>
      </axis>
      <physics>
        <ode>
          <implicit_spring_damper>1</implicit_spring_damper>
        </ode>
      </physics>
    </joint>
<!--
    <link name='iris/imugt_link'>
      <pose>0 0 0 0 -0 0</pose>
      <inertial>
        <pose>0 0 0 0 -0 0</pose>
        <mass>1e-02</mass>
        <inertia>
          <ixx>0.0002</ixx>
          <ixy>0</ixy>
          <ixz>0</ixz>
          <iyy>0.0002</iyy>
          <iyz>0</iyz>
          <izz>0.0002</izz>
        </inertia>
      </inertial>
    </link>
    <joint name='iris/imugt_joint' type='revolute'>
      <child>iris/imugt_link</child>
      <parent>base_link</parent>
      <axis>
        <xyz>0 0 1</xyz>
        <limit>
          <lower>0</lower>
          <upper>0</upper>
          <effort>0</effort>
          <velocity>0</velocity>
        </limit>
        <dynamics>
          <spring_reference>0</spring_reference>
          <spring_stiffness>0</spring_stiffness>
        </dynamics>
        <use_parent_model_frame>1</use_parent_model_frame>
      </axis>
    </joint>
-->

    <!-- définition des rotors : position, inertie, collision, visuel (.dae), liaison -->
    <link name='rotor_0'>
      <pose>0 -0.275 0.0115 0 -0 0</pose>
      <inertial>
        <pose>0 0 0 0 -0 0</pose>
        <mass>0.025</mass>
        <inertia>
          <ixx>9.75e-06</ixx>
          <ixy>0</ixy>
          <ixz>0</ixz>
          <iyy>0.000166704</iyy>
          <iyz>0</iyz>
          <izz>0.000167604</izz>
        </inertia>
      </inertial>
      <collision name='rotor_0_collision'>
        <pose>0 0 0 0 -0 0</pose>
        <geometry>
          <cylinder>
            <length>0.006</length>
            <radius>0.118</radius>
          </cylinder>
        </geometry>
        <surface>
          <contact>
            <ode/>
          </contact>
          <friction>
            <ode/>
          </friction>
        </surface>
      </collision>
      <visual name='rotor_0_visual'>
        <pose>0 0 0 0 -0 0</pose>
        <geometry>
          <mesh>
            <scale>-1 1 1</scale>
            <uri>model://iris_with_standoffs/meshes/dji_f550_prop.dae</uri>
          </mesh>
        </geometry>
        <material>
          <script>
            <name>Gazebo/White</name>
            <uri>__default__</uri>
          </script>
        </material>
      </visual>
      <gravity>1</gravity>
      <velocity_decay/>
      <self_collide>0</self_collide>
    </link>
    <joint name='rotor_0_joint' type='revolute'>
      <child>rotor_0</child>
      <parent>base_link</parent>
      <axis>
        <xyz>0 0 1</xyz>
        <limit>
          <lower>-1e+16</lower>
          <upper>1e+16</upper>
        </limit>
        <dynamics>
          <damping>0.004</damping>
        </dynamics>
        <use_parent_model_frame>1</use_parent_model_frame>
      </axis>
      <physics>
        <ode>
          <implicit_spring_damper>1</implicit_spring_damper>
        </ode>
      </physics>
    </joint>
    <link name='rotor_1'>
      <pose>0 0.275 0.0115 0 -0 0</pose>
      <inertial>
        <pose>0 0 0 0 -0 0</pose>
        <mass>0.025</mass>
        <inertia>
          <ixx>9.75e-06</ixx>
          <ixy>0</ixy>
          <ixz>0</ixz>
          <iyy>0.000166704</iyy>
          <iyz>0</iyz>
          <izz>0.000167604</izz>
        </inertia>
      </inertial>
      <collision name='rotor_1_collision'>
        <pose>0 0 0 0 -0 0</pose>
        <geometry>
          <cylinder>
            <length>0.006</length>
            <radius>0.118</radius>
          </cylinder>
        </geometry>
        <surface>
          <contact>
            <ode/>
          </contact>
          <friction>
            <ode/>
          </friction>
        </surface>
      </collision>
      <visual name='rotor_1_visual'>
        <pose>0 0 0 0 -0 0</pose>
        <geometry>
          <mesh>
            <scale>1 1 1</scale>
            <uri>model://iris_with_standoffs/meshes/dji_f550_prop.dae</uri>
          </mesh>
        </geometry>
        <material>
          <script>
            <name>Gazebo/White</name>
            <uri>__default__</uri>
          </script>
        </material>
      </visual>
      <gravity>1</gravity>
      <velocity_decay/>
      <self_collide>0</self_collide>
    </link>
    <joint name='rotor_1_joint' type='revolute'>
      <child>rotor_1</child>
      <parent>base_link</parent>
      <axis>
        <xyz>0 0 1</xyz>
        <limit>
          <lower>-1e+16</lower>
          <upper>1e+16</upper>
        </limit>
        <dynamics>
          <damping>0.004</damping>
        </dynamics>
        <use_parent_model_frame>1</use_parent_model_frame>
      </axis>
      <physics>
        <ode>
          <implicit_spring_damper>1</implicit_spring_damper>
        </ode>
      </physics>
    </joint>
    <link name='rotor_2'>
      <pose>0.238157 0.1375 0.0115 0 -0 0</pose>
      <inertial>
        <pose>0 0 0 0 -0 0</pose>
        <mass>0.025</mass>
        <inertia>
          <ixx>9.75e-06</ixx>
          <ixy>0</ixy>
          <ixz>0</ixz>
          <iyy>0.000166704</iyy>
          <iyz>0</iyz>
          <izz>0.000167604</izz>
        </inertia>
      </inertial>
      <collision name='rotor_2_collision'>
        <pose>0 0 0 0 -0 0</pose>
        <geometry>
          <cylinder>
            <length>0.006</length>
            <radius>0.118</radius>
          </cylinder>
        </geometry>
        <surface>
          <contact>
            <ode/>
          </contact>
          <friction>
            <ode/>
          </friction>
        </surface>
      </collision>
      <visual name='rotor_2_visual'>
        <pose>0 0 0 0 -0 0</pose>
        <geometry>
          <mesh>
            <scale>-1 1 1</scale>
            <uri>model://iris_with_standoffs/meshes/dji_f550_prop.dae</uri>
          </mesh>
        </geometry>
        <material>
          <script>
            <name>Gazebo/White</name>
            <uri>__default__</uri>
          </script>
        </material>
      </visual>
      <gravity>1</gravity>
      <velocity_decay/>
      <self_collide>0</self_collide>
    </link>
    <joint name='rotor_2_joint' type='revolute'>
      <child>rotor_2</child>
      <parent>base_link</parent>
      <axis>
        <xyz>0 0 1</xyz>
        <limit>
          <lower>-1e+16</lower>
          <upper>1e+16</upper>
        </limit>
        <dynamics>
          <damping>0.004</damping>
        </dynamics>
        <use_parent_model_frame>1</use_parent_model_frame>
      </axis>
      <physics>
        <ode>
          <implicit_spring_damper>1</implicit_spring_damper>
        </ode>
      </physics>
    </joint>
    <link name='rotor_3'>
      <pose>-0.238157 -0.1375 0.0115 0 -0 0</pose>
      <inertial>
        <pose>0 0 0 0 -0 0</pose>
        <mass>0.025</mass>
        <inertia>
          <ixx>9.75e-06</ixx>
          <ixy>0</ixy>
          <ixz>0</ixz>
          <iyy>0.000166704</iyy>
          <iyz>0</iyz>
          <izz>0.000167604</izz>
        </inertia>
      </inertial>
      <collision name='rotor_3_collision'>
        <pose>0 0 0 0 -0 0</pose>
        <geometry>
          <cylinder>
            <length>0.006</length>
            <radius>0.118</radius>
          </cylinder>
        </geometry>
        <surface>
          <contact>
            <ode/>
          </contact>
          <friction>
            <ode/>
          </friction>
        </surface>
      </collision>
      <visual name='rotor_3_visual'>
        <pose>0 0 0 0 -0 0</pose>
        <geometry>
          <mesh>
            <scale>1 1 1</scale>
            <uri>model://iris_with_standoffs/meshes/dji_f550_prop.dae</uri>
          </mesh>
        </geometry>
        <material>
          <script>
            <name>Gazebo/White</name>
            <uri>__default__</uri>
          </script>
        </material>
      </visual>
      <gravity>1</gravity>
      <velocity_decay/>
      <self_collide>0</self_collide>
    </link>
    <joint name='rotor_3_joint' type='revolute'>
      <child>rotor_3</child>
      <parent>base_link</parent>
      <axis>
        <xyz>0 0 1</xyz>
        <limit>
          <lower>-1e+16</lower>
          <upper>1e+16</upper>
        </limit>
        <dynamics>
          <damping>0.004</damping>
        </dynamics>
        <use_parent_model_frame>1</use_parent_model_frame>
      </axis>
      <physics>
        <ode>
          <implicit_spring_damper>1</implicit_spring_damper>
        </ode>
      </physics>
    </joint>
    <link name='rotor_4'>
      <pose>0.238157 -0.1375 0.0115 0 -0 0</pose>
      <inertial>
        <pose>0 0 0 0 -0 0</pose>
        <mass>0.025</mass>
        <inertia>
          <ixx>9.75e-06</ixx>
          <ixy>0</ixy>
          <ixz>0</ixz>
          <iyy>0.000166704</iyy>
          <iyz>0</iyz>
          <izz>0.000167604</izz>
        </inertia>
      </inertial>
      <collision name='rotor_4_collision'>
        <pose>0 0 0 0 -0 0</pose>
        <geometry>
          <cylinder>
            <length>0.006</length>
            <radius>0.118</radius>
          </cylinder>
        </geometry>
        <surface>
          <contact>
            <ode/>
          </contact>
          <friction>
            <ode/>
          </friction>
        </surface>
      </collision>
      <visual name='rotor_4_visual'>
        <pose>0 0 0 0 -0 0</pose>
        <geometry>
          <mesh>
            <scale>1 1 1</scale>
            <uri>model://iris_with_standoffs/meshes/dji_f550_prop.dae</uri>
          </mesh>
        </geometry>
        <material>
          <script>
            <name>Gazebo/White</name>
            <uri>__default__</uri>
          </script>
        </material>
      </visual>
      <gravity>1</gravity>
      <velocity_decay/>
      <self_collide>0</self_collide>
    </link>
    <joint name='rotor_4_joint' type='revolute'>
      <child>rotor_4</child>
      <parent>base_link</parent>
      <axis>
        <xyz>0 0 1</xyz>
        <limit>
          <lower>-1e+16</lower>
          <upper>1e+16</upper>
        </limit>
        <dynamics>
          <damping>0.004</damping>
        </dynamics>
        <use_parent_model_frame>1</use_parent_model_frame>
      </axis>
      <physics>
        <ode>
          <implicit_spring_damper>1</implicit_spring_damper>
        </ode>
      </physics>
    </joint>
    <link name='rotor_5'>
      <pose>-0.238157 0.1375 0.0115 0 -0 0</pose>
      <inertial>
        <pose>0 0 0 0 -0 0</pose>
        <mass>0.025</mass>
        <inertia>
          <ixx>9.75e-06</ixx>
          <ixy>0</ixy>
          <ixz>0</ixz>
          <iyy>0.000166704</iyy>
          <iyz>0</iyz>
          <izz>0.000167604</izz>
        </inertia>
      </inertial>
      <collision name='rotor_5_collision'>
        <pose>0 0 0 0 -0 0</pose>
        <geometry>
          <cylinder>
            <length>0.006</length>
            <radius>0.118</radius>
          </cylinder>
        </geometry>
        <surface>
          <contact>
            <ode/>
          </contact>
          <friction>
            <ode/>
          </friction>
        </surface>
      </collision>
      <visual name='rotor_5_visual'>
        <pose>0 0 0 0 -0 0</pose>
        <geometry>
          <mesh>
            <scale>-1 1 1</scale>
            <uri>model://iris_with_standoffs/meshes/dji_f550_prop.dae</uri>
          </mesh>
        </geometry>
        <material>
          <script>
            <name>Gazebo/White</name>
            <uri>__default__</uri>
          </script>
        </material>
      </visual>
      <gravity>1</gravity>
      <velocity_decay/>
      <self_collide>0</self_collide>
    </link>
    <joint name='rotor_5_joint' type='revolute'>
      <child>rotor_5</child>
      <parent>base_link</parent>
      <axis>
        <xyz>0 0 1</xyz>
        <limit>
          <lower>-1e+16</lower>
          <upper>1e+16</upper>
        </limit>
        <dynamics>
          <damping>0.004</damping>
        </dynamics>
        <use_parent_model_frame>1</use_parent_model_frame>
      </axis>
      <physics>
        <ode>
          <implicit_spring_damper>1</implicit_spring_damper>
        </ode>
      </physics>
    </joint>
    <static>0</static>
  </model>
</sdf>
